Traceback (most recent call last):
  File "<frozen runpy>", line 198, in _run_module_as_main
  File "<frozen runpy>", line 88, in _run_code
  File "/opt/homebrew/Cellar/python@3.11/3.11.4_1/Frameworks/Python.framework/Versions/3.11/lib/python3.11/http/server.py", line 1313, in <module>
    test(
  File "/opt/homebrew/Cellar/python@3.11/3.11.4_1/Frameworks/Python.framework/Versions/3.11/lib/python3.11/http/server.py", line 1260, in test
    with ServerClass(addr, HandlerClass) as httpd:
         ^^^^^^^^^^^^^^^^^^^^^^^^^^^^^^^
  File "/opt/homebrew/Cellar/python@3.11/3.11.4_1/Frameworks/Python.framework/Versions/3.11/lib/python3.11/socketserver.py", line 456, in __init__
    self.server_bind()
  File "/opt/homebrew/Cellar/python@3.11/3.11.4_1/Frameworks/Python.framework/Versions/3.11/lib/python3.11/http/server.py", line 1307, in server_bind
    return super().server_bind()
           ^^^^^^^^^^^^^^^^^^^^^
  File "/opt/homebrew/Cellar/python@3.11/3.11.4_1/Frameworks/Python.framework/Versions/3.11/lib/python3.11/http/server.py", line 136, in server_bind
    socketserver.TCPServer.server_bind(self)
  File "/opt/homebrew/Cellar/python@3.11/3.11.4_1/Frameworks/Python.framework/Versions/3.11/lib/python3.11/socketserver.py", line 472, in server_bind
    self.socket.bind(self.server_address)
OSError: [Errno 48] Address already in use
